Workbook

Sheet Read me
A1: Overhead LLC | 36-month planning model
A2: General-purpose business plan | September 13, 2026
A3: All figures are illustrative assumptions, not actual results.
A4: Change blue input values on Assumptions and Acquisition. Formula sheets recalculate in Excel.
A5: Month 1 starts with funded execution; months 1-2 have no paid additions.
A6: Base, Downside, and Upside use the same operating budget and $175,000 capital scenario.
A7: Monthly churn affects opening accounts. New additions contribute half a billed month.
A8: Net revenue deducts a 1% refund/credit allowance. Fees use gross charges.
A9: No debt, capex, working capital lag, historical assets, or existing balances are included.
A10: The 25% annual tax reserve is a planning assumption, not an LLC tax determination.
A11: Model values were independently calculated in Python and exported to the companion CSV/JSON.
A12: Formula cells may show blank previews until opened in Excel or another recalculating spreadsheet app.

Sheet Assumptions
A1: Input | B1: Value | C1: Basis
A2: Opening capital | B2: 175000 | C2: Illustrative new contribution; not existing company cash
A3: Silver monthly price | B3: 59 | C3: Published
A4: Gold monthly price | B4: 129 | C4: Published
A5: Black monthly price | B5: 299 | C5: Published
A6: Silver mix | B6: 0.4 | C6: Assumption
A7: Gold mix | B7: 0.45 | C7: Assumption
A8: Black mix | B8: 0.15 | C8: Assumption
A9: Blended ARPA | B9: =SUMPRODUCT(B3:B5,B6:B8) -> 126.5 | C9: Calculated
A10: Base monthly churn | B10: 0.02 | C10: Assumption
A11: Refunds/credits rate | B11: 0.01 | C11: Assumption
A12: Processing + Billing rate | B12: 0.036 | C12: 2.9% domestic card + 0.7% Stripe Billing
A13: Fixed payment fee | B13: 0.3 | C13: Per billed workspace-month approximation
A14: Infrastructure / billable month | B14: 5 | C14: Assumption
A15: Support / billable month | B15: 10 | C15: Assumption
A16: Onboarding / new paid workspace | B16: 60 | C16: Assumption
A17: Tax reserve | B17: 0.25 | C17: Applied to positive annual operating income; paid at year-end
A18: Minimum cash reserve | B18: 30000 | C18: Management target
A19: Downside acquisition factor | B19: 0.6 | C19: Assumption
A20: Downside churn | B20: 0.035 | C20: Assumption
A21: Downside price factor | B21: 0.9 | C21: Assumption
... A23: Upside churn | B23: 0.015 | C23: Assumption
A25: Annual budget | B25: Year 1 | C25: Year 2 | D25: Year 3
A26: Product | B26: 48000 | C26: 84000 | D26: 120000
A27: Founder | B27: 36000 | C27: 48000 | D27: 60000
A28: Marketing | B28: 18000 | C28: 36000 | D28: 60000
A29: General | B29: 12000 | C29: 18000 | D29: 24000
A30: Monthly fixed opex | B30: =SUM(B26:B29)/12 -> 9500 | C30: =SUM(C26:C29)/12 -> 15500 | D30: =SUM(D26:D29)/12 -> 22000

Sheet Acquisition
A1: Planning month | B1: Base gross new paid | C1: Launch expense
A2: 1 | B2: 0 | C2: 10000
A3: 2 | B3: 0 | C3: 5000
A4: 3 | B4: 3 | C4: 0
A5: 4 | B5: 5 | C5: 0
A6: 5 | B6: 7 | C6: 0
A7: 6 | B7: 9 | C7: 0
A8: 7 | B8: 11 | C8: 0
A9: 8 | B9: 13 | C9: 0
A10: 9 | B10: 15 | C10: 0
A11: 10 | B11: 17 | C11: 0
A12: 11 | B12: 19 | C12: 0
A13: 12 | B13: 21 | C13: 0
... A37: 36 | B37: 40 | C37: 0

Sheet Base
A1: Month | B1: Year | C1: Opening paid | D1: Churned | E1: New paid | F1: Ending paid | G1: Billed equivalent | H1: Gross charges | I1: Credits/refunds | J1: Net revenue | K1: Payment fees | L1: Service delivery | M1: Onboarding | N1: Total COGS | O1: Gross profit | P1: Fixed opex | Q1: Launch costs | R1: Operating profit | S1: Tax reserve | T1: Net income | U1: Ending cash | V1: Exit MRR | W1: Exit ARR
A2: 1 | B2: =INT((A2-1)/12)+1 -> 1 | C2: =0 -> 0 | D2: =C2*Assumptions!$B$10 -> 0 | E2: =Acquisition!B2*1 -> 0 | F2: =C2-D2+E2 -> 0 | G2: =C2-D2+E2/2 -> 0 | H2: =G2*Assumptions!$B$9 -> 0 | I2: =H2*Assumptions!$B$11 -> 0 | J2: =H2-I2 -> 0 | K2: =H2*Assumptions!$B$12+G2*Assumptions!$B$13 -> 0 | L2: =G2*(Assumptions!$B$14+Assumptions!$B$15) -> 0 | M2: =E2*Assumptions!$B$16 -> 0 | N2: =SUM(K2:M2) -> 0 | O2: =J2-N2 -> 0 | P2: =INDEX(Assumptions!$B$30:$D$30,1,B2) -> 9500 | Q2: =Acquisition!C2 -> 10000 | R2: =O2-P2-Q2 -> -19500 | S2: =0 -> 0 | T2: =R2-S2 -> -19500 | U2: =Assumptions!$B$2+T2 -> 155500 | V2: =F2*Assumptions!$B$9 -> 0 | W2: =V2*12 -> 0
A3: 2 | B3: =INT((A3-1)/12)+1 -> 1 | C3: =F2 -> 0 | D3: =C3*Assumptions!$B$10 -> 0 | E3: =Acquisition!B3*1 -> 0 | F3: =C3-D3+E3 -> 0 | G3: =C3-D3+E3/2 -> 0 | H3: =G3*Assumptions!$B$9 -> 0 | I3: =H3*Assumptions!$B$11 -> 0 | J3: =H3-I3 -> 0 | K3: =H3*Assumptions!$B$12+G3*Assumptions!$B$13 -> 0 | L3: =G3*(Assumptions!$B$14+Assumptions!$B$15) -> 0 | M3: =E3*Assumptions!$B$16 -> 0 | N3: =SUM(K3:M3) -> 0 | O3: =J3-N3 -> 0 | P3: =INDEX(Assumptions!$B$30:$D$30,1,B3) -> 9500 | Q3: =Acquisition!C3 -> 5000 | R3: =O3-P3-Q3 -> -14500 | S3: =0 -> 0 | T3: =R3-S3 -> -14500 | U3: =U2+T3 -> 141000 | V3: =F3*Assumptions!$B$9 -> 0 | W3: =V3*12 -> 0
A4: 3 | B4: =INT((A4-1)/12)+1 -> 1 | C4: =F3 -> 0 | D4: =C4*Assumptions!$B$10 -> 0 | E4: =Acquisition!B4*1 -> 3 | F4: =C4-D4+E4 -> 3 | G4: =C4-D4+E4/2 -> 1.5 | H4: =G4*Assumptions!$B$9 -> 189.75 | I4: =H4*Assumptions!$B$11 -> 1.8975 | J4: =H4-I4 -> 187.8525 | K4: =H4*Assumptions!$B$12+G4*Assumptions!$B$13 -> 7.281 | L4: =G4*(Assumptions!$B$14+Assumptions!$B$15) -> 22.5 | M4: =E4*Assumptions!$B$16 -> 180 | N4: =SUM(K4:M4) -> 209.781 | O4: =J4-N4 -> -21.9285 | P4: =INDEX(Assumptions!$B$30:$D$30,1,B4) -> 9500 | Q4: =Acquisition!C4 -> 0 | R4: =O4-P4-Q4 -> -9521.9285 | S4: =0 -> 0 | T4: =R4-S4 -> -9521.9285 | U4: =U3+T4 -> 131478.07 | V4: =F4*Assumptions!$B$9 -> 379.5 | W4: =V4*12 -> 4554
A5: 4 | B5: =INT((A5-1)/12)+1 -> 1 | C5: =F4 -> 3 | D5: =C5*Assumptions!$B$10 -> 0.06 | E5: =Acquisition!B5*1 -> 5 | F5: =C5-D5+E5 -> 7.94 | G5: =C5-D5+E5/2 -> 5.44 | H5: =G5*Assumptions!$B$9 -> 688.16 | I5: =H5*Assumptions!$B$11 -> 6.8816 | J5: =H5-I5 -> 681.2784 | K5: =H5*Assumptions!$B$12+G5*Assumptions!$B$13 -> 26.40576 | L5: =G5*(Assumptions!$B$14+Assumptions!$B$15) -> 81.6 | M5: =E5*Assumptions!$B$16 -> 300 | N5: =SUM(K5:M5) -> 408.00576 | O5: =J5-N5 -> 273.27264 | P5: =INDEX(Assumptions!$B$30:$D$30,1,B5) -> 9500 | Q5: =Acquisition!C5 -> 0 | R5: =O5-P5-Q5 -> -9226.7274 | S5: =0 -> 0 | T5: =R5-S5 -> -9226.7274 | U5: =U4+T5 -> 122251.34 | V5: =F5*Assumptions!$B$9 -> 1004.41 | W5: =V5*12 -> 12052.92
A6: 5 | B6: =INT((A6-1)/12)+1 -> 1 | C6: =F5 -> 7.94 | D6: =C6*Assumptions!$B$10 -> 0.1588 | E6: =Acquisition!B6*1 -> 7 | F6: =C6-D6+E6 -> 14.7812 | G6: =C6-D6+E6/2 -> 11.2812 | H6: =G6*Assumptions!$B$9 -> 1427.0718 | I6: =H6*Assumptions!$B$11 -> 14.270718 | J6: =H6-I6 -> 1412.8011 | K6: =H6*Assumptions!$B$12+G6*Assumptions!$B$13 -> 54.758945 | L6: =G6*(Assumptions!$B$14+Assumptions!$B$15) -> 169.218 | M6: =E6*Assumptions!$B$16 -> 420 | N6: =SUM(K6:M6) -> 643.97694 | O6: =J6-N6 -> 768.82414 | P6: =INDEX(Assumptions!$B$30:$D$30,1,B6) -> 9500 | Q6: =Acquisition!C6 -> 0 | R6: =O6-P6-Q6 -> -8731.1759 | S6: =0 -> 0 | T6: =R6-S6 -> -8731.1759 | U6: =U5+T6 -> 113520.17 | V6: =F6*Assumptions!$B$9 -> 1869.8218 | W6: =V6*12 -> 22437.862
A7: 6 | B7: =INT((A7-1)/12)+1 -> 1 | C7: =F6 -> 14.7812 | D7: =C7*Assumptions!$B$10 -> 0.295624 | E7: =Acquisition!B7*1 -> 9 | F7: =C7-D7+E7 -> 23.485576 | G7: =C7-D7+E7/2 -> 18.985576 | H7: =G7*Assumptions!$B$9 -> 2401.6754 | I7: =H7*Assumptions!$B$11 -> 24.016754 | J7: =H7-I7 -> 2377.6586 | K7: =H7*Assumptions!$B$12+G7*Assumptions!$B$13 -> 92.155986 | L7: =G7*(Assumptions!$B$14+Assumptions!$B$15) -> 284.78364 | M7: =E7*Assumptions!$B$16 -> 540 | N7: =SUM(K7:M7) -> 916.93963 | O7: =J7-N7 -> 1460.719 | P7: =INDEX(Assumptions!$B$30:$D$30,1,B7) -> 9500 | Q7: =Acquisition!C7 -> 0 | R7: =O7-P7-Q7 -> -8039.281 | S7: =0 -> 0 | T7: =R7-S7 -> -8039.281 | U7: =U6+T7 -> 105480.89 | V7: =F7*Assumptions!$B$9 -> 2970.9254 | W7: =V7*12 -> 35651.104
A8: 7 | B8: =INT((A8-1)/12)+1 -> 1 | C8: =F7 -> 23.485576 | D8: =C8*Assumptions!$B$10 -> 0.46971152 | E8: =Acquisition!B8*1 -> 11 | F8: =C8-D8+E8 -> 34.015864 | G8: =C8-D8+E8/2 -> 28.515864 | H8: =G8*Assumptions!$B$9 -> 3607.2569 | I8: =H8*Assumptions!$B$11 -> 36.072569 | J8: =H8-I8 -> 3571.1843 | K8: =H8*Assumptions!$B$12+G8*Assumptions!$B$13 -> 138.41601 | L8: =G8*(Assumptions!$B$14+Assumptions!$B$15) -> 427.73797 | M8: =E8*Assumptions!$B$16 -> 660 | N8: =SUM(K8:M8) -> 1226.154 | O8: =J8-N8 -> 2345.0303 | P8: =INDEX(Assumptions!$B$30:$D$30,1,B8) -> 9500 | Q8: =Acquisition!C8 -> 0 | R8: =O8-P8-Q8 -> -7154.9697 | S8: =0 -> 0 | T8: =R8-S8 -> -7154.9697 | U8: =U7+T8 -> 98325.918 | V8: =F8*Assumptions!$B$9 -> 4303.0069 | W8: =V8*12 -> 51636.082
A9: 8 | B9: =INT((A9-1)/12)+1 -> 1 | C9: =F8 -> 34.015864 | D9: =C9*Assumptions!$B$10 -> 0.68031729 | E9: =Acquisition!B9*1 -> 13 | F9: =C9-D9+E9 -> 46.335547 | G9: =C9-D9+E9/2 -> 39.835547 | H9: =G9*Assumptions!$B$9 -> 5039.1967 | I9: =H9*Assumptions!$B$11 -> 50.391967 | J9: =H9-I9 -> 4988.8048 | K9: =H9*Assumptions!$B$12+G9*Assumptions!$B$13 -> 193.36175 | L9: =G9*(Assumptions!$B$14+Assumptions!$B$15) -> 597.53321 | M9: =E9*Assumptions!$B$16 -> 780 | N9: =SUM(K9:M9) -> 1570.895 | O9: =J9-N9 -> 3417.9098 | P9: =INDEX(Assumptions!$B$30:$D$30,1,B9) -> 9500 | Q9: =Acquisition!C9 -> 0 | R9: =O9-P9-Q9 -> -6082.0902 | S9: =0 -> 0 | T9: =R9-S9 -> -6082.0902 | U9: =U8+T9 -> 92243.827 | V9: =F9*Assumptions!$B$9 -> 5861.4467 | W9: =V9*12 -> 70337.361
A10: 9 | B10: =INT((A10-1)/12)+1 -> 1 | C10: =F9 -> 46.335547 | D10: =C10*Assumptions!$B$10 -> 0.92671094 | E10: =Acquisition!B10*1 -> 15 | F10: =C10-D10+E10 -> 60.408836 | G10: =C10-D10+E10/2 -> 52.908836 | H10: =G10*Assumptions!$B$9 -> 6692.9678 | I10: =H10*Assumptions!$B$11 -> 66.929678 | J10: =H10-I10 -> 6626.0381 | K10: =H10*Assumptions!$B$12+G10*Assumptions!$B$13 -> 256.81949 | L10: =G10*(Assumptions!$B$14+Assumptions!$B$15) -> 793.63254 | M10: =E10*Assumptions!$B$16 -> 900 | N10: =SUM(K10:M10) -> 1950.452 | O10: =J10-N10 -> 4675.5861 | P10: =INDEX(Assumptions!$B$30:$D$30,1,B10) -> 9500 | Q10: =Acquisition!C10 -> 0 | R10: =O10-P10-Q10 -> -4824.4139 | S10: =0 -> 0 | T10: =R10-S10 -> -4824.4139 | U10: =U9+T10 -> 87419.413 | V10: =F10*Assumptions!$B$9 -> 7641.7178 | W10: =V10*12 -> 91700.613
A11: 10 | B11: =INT((A11-1)/12)+1 -> 1 | C11: =F10 -> 60.408836 | D11: =C11*Assumptions!$B$10 -> 1.2081767 | E11: =Acquisition!B11*1 -> 17 | F11: =C11-D11+E11 -> 76.20066 | G11: =C11-D11+E11/2 -> 67.70066 | H11: =G11*Assumptions!$B$9 -> 8564.1334 | I11: =H11*Assumptions!$B$11 -> 85.641334 | J11: =H11-I11 -> 8478.4921 | K11: =H11*Assumptions!$B$12+G11*Assumptions!$B$13 -> 328.619 | L11: =G11*(Assumptions!$B$14+Assumptions!$B$15) -> 1015.5099 | M11: =E11*Assumptions!$B$16 -> 1020 | N11: =SUM(K11:M11) -> 2364.1289 | O11: =J11-N11 -> 6114.3632 | P11: =INDEX(Assumptions!$B$30:$D$30,1,B11) -> 9500 | Q11: =Acquisition!C11 -> 0 | R11: =O11-P11-Q11 -> -3385.6368 | S11: =0 -> 0 | T11: =R11-S11 -> -3385.6368 | U11: =U10+T11 -> 84033.777 | V11: =F11*Assumptions!$B$9 -> 9639.3834 | W11: =V11*12 -> 115672.6
A12: 11 | B12: =INT((A12-1)/12)+1 -> 1 | C12: =F11 -> 76.20066 | D12: =C12*Assumptions!$B$10 -> 1.5240132 | E12: =Acquisition!B12*1 -> 19 | F12: =C12-D12+E12 -> 93.676646 | G12: =C12-D12+E12/2 -> 84.176646 | H12: =G12*Assumptions!$B$9 -> 10648.346 | I12: =H12*Assumptions!$B$11 -> 106.48346 | J12: =H12-I12 -> 10541.862 | K12: =H12*Assumptions!$B$12+G12*Assumptions!$B$13 -> 408.59344 | L12: =G12*(Assumptions!$B$14+Assumptions!$B$15) -> 1262.6497 | M12: =E12*Assumptions!$B$16 -> 1140 | N12: =SUM(K12:M12) -> 2811.2431 | O12: =J12-N12 -> 7730.6192 | P12: =INDEX(Assumptions!$B$30:$D$30,1,B12) -> 9500 | Q12: =Acquisition!C12 -> 0 | R12: =O12-P12-Q12 -> -1769.3808 | S12: =0 -> 0 | T12: =R12-S12 -> -1769.3808 | U12: =U11+T12 -> 82264.396 | V12: =F12*Assumptions!$B$9 -> 11850.096 | W12: =V12*12 -> 142201.15
A13: 12 | B13: =INT((A13-1)/12)+1 -> 1 | C13: =F12 -> 93.676646 | D13: =C13*Assumptions!$B$10 -> 1.8735329 | E13: =Acquisition!B13*1 -> 21 | F13: =C13-D13+E13 -> 112.80311 | G13: =C13-D13+E13/2 -> 102.30311 | H13: =G13*Assumptions!$B$9 -> 12941.344 | I13: =H13*Assumptions!$B$11 -> 129.41344 | J13: =H13-I13 -> 12811.93 | K13: =H13*Assumptions!$B$12+G13*Assumptions!$B$13 -> 496.57931 | L13: =G13*(Assumptions!$B$14+Assumptions!$B$15) -> 1534.5467 | M13: =E13*Assumptions!$B$16 -> 1260 | N13: =SUM(K13:M13) -> 3291.126 | O13: =J13-N13 -> 9520.8044 | P13: =INDEX(Assumptions!$B$30:$D$30,1,B13) -> 9500 | Q13: =Acquisition!C13 -> 0 | R13: =O13-P13-Q13 -> 20.804394 | S13: =MAX(SUM(R2:R13),0)*Assumptions!$B$17 -> 0 | T13: =R13-S13 -> 20.804394 | U13: =U12+T13 -> 82285.2 | V13: =F13*Assumptions!$B$9 -> 14269.594 | W13: =V13*12 -> 171235.13
A14: 13 | B14: =INT((A14-1)/12)+1 -> 2 | C14: =F13 -> 112.80311 | D14: =C14*Assumptions!$B$10 -> 2.2560623 | E14: =Acquisition!B14*1 -> 25 | F14: =C14-D14+E14 -> 135.54705 | G14: =C14-D14+E14/2 -> 123.04705 | H14: =G14*Assumptions!$B$9 -> 15565.452 | I14: =H14*Assumptions!$B$11 -> 155.65452 | J14: =H14-I14 -> 15409.797 | K14: =H14*Assumptions!$B$12+G14*Assumptions!$B$13 -> 597.27039 | L14: =G14*(Assumptions!$B$14+Assumptions!$B$15) -> 1845.7058 | M14: =E14*Assumptions!$B$16 -> 1500 | N14: =SUM(K14:M14) -> 3942.9762 | O14: =J14-N14 -> 11466.821 | P14: =INDEX(Assumptions!$B$30:$D$30,1,B14) -> 15500 | Q14: =Acquisition!C14 -> 0 | R14: =O14-P14-Q14 -> -4033.1787 | S14: =0 -> 0 | T14: =R14-S14 -> -4033.1787 | U14: =U13+T14 -> 78252.022 | V14: =F14*Assumptions!$B$9 -> 17146.702 | W14: =V14*12 -> 205760.42
A15: 14 | B15: =INT((A15-1)/12)+1 -> 2 | C15: =F14 -> 135.54705 | D15: =C15*Assumptions!$B$10 -> 2.710941 | E15: =Acquisition!B15*1 -> 25 | F15: =C15-D15+E15 -> 157.83611 | G15: =C15-D15+E15/2 -> 145.33611 | H15: =G15*Assumptions!$B$9 -> 18385.018 | I15: =H15*Assumptions!$B$11 -> 183.85018 | J15: =H15-I15 -> 18201.168 | K15: =H15*Assumptions!$B$12+G15*Assumptions!$B$13 -> 705.46148 | L15: =G15*(Assumptions!$B$14+Assumptions!$B$15) -> 2180.0417 | M15: =E15*Assumptions!$B$16 -> 1500 | N15: =SUM(K15:M15) -> 4385.5031 | O15: =J15-N15 -> 13815.665 | P15: =INDEX(Assumptions!$B$30:$D$30,1,B15) -> 15500 | Q15: =Acquisition!C15 -> 0 | R15: =O15-P15-Q15 -> -1684.3354 | S15: =0 -> 0 | T15: =R15-S15 -> -1684.3354 | U15: =U14+T15 -> 76567.686 | V15: =F15*Assumptions!$B$9 -> 19966.268 | W15: =V15*12 -> 239595.22
A16: 15 | B16: =INT((A16-1)/12)+1 -> 2 | C16: =F15 -> 157.83611 | D16: =C16*Assumptions!$B$10 -> 3.1567222 | E16: =Acquisition!B16*1 -> 25 | F16: =C16-D16+E16 -> 179.67939 | G16: =C16-D16+E16/2 -> 167.17939 | H16: =G16*Assumptions!$B$9 -> 21148.193 | I16: =H16*Assumptions!$B$11 -> 211.48193 | J16: =H16-I16 -> 20936.711 | K16: =H16*Assumptions!$B$12+G16*Assumptions!$B$13 -> 811.48875 | L16: =G16*(Assumptions!$B$14+Assumptions!$B$15) -> 2507.6908 | M16: =E16*Assumptions!$B$16 -> 1500 | N16: =SUM(K16:M16) -> 4819.1796 | O16: =J16-N16 -> 16117.531 | P16: =INDEX(Assumptions!$B$30:$D$30,1,B16) -> 15500 | Q16: =Acquisition!C16 -> 0 | R16: =O16-P16-Q16 -> 617.53108 | S16: =0 -> 0 | T16: =R16-S16 -> 617.53108 | U16: =U15+T16 -> 77185.217 | V16: =F16*Assumptions!$B$9 -> 22729.443 | W16: =V16*12 -> 272753.31
A17: 16 | B17: =INT((A17-1)/12)+1 -> 2 | C17: =F16 -> 179.67939 | D17: =C17*Assumptions!$B$10 -> 3.5935878 | E17: =Acquisition!B17*1 -> 25 | F17: =C17-D17+E17 -> 201.0858 | G17: =C17-D17+E17/2 -> 188.5858 | H17: =G17*Assumptions!$B$9 -> 23856.104 | I17: =H17*Assumptions!$B$11 -> 238.56104 | J17: =H17-I17 -> 23617.543 | K17: =H17*Assumptions!$B$12+G17*Assumptions!$B$13 -> 915.39547 | L17: =G17*(Assumptions!$B$14+Assumptions!$B$15) -> 2828.787 | M17: =E17*Assumptions!$B$16 -> 1500 | N17: =SUM(K17:M17) -> 5244.1825 | O17: =J17-N17 -> 18373.36 | P17: =INDEX(Assumptions!$B$30:$D$30,1,B17) -> 15500 | Q17: =Acquisition!C17 -> 0 | R17: =O17-P17-Q17 -> 2873.3602 | S17: =0 -> 0 | T17: =R17-S17 -> 2873.3602 | U17: =U16+T17 -> 80058.577 | V17: =F17*Assumptions!$B$9 -> 25437.354 | W17: =V17*12 -> 305248.24
A18: 17 | B18: =INT((A18-1)/12)+1 -> 2 | C18: =F17 -> 201.0858 | D18: =C18*Assumptions!$B$10 -> 4.021716 | E18: =Acquisition!B18*1 -> 25 | F18: =C18-D18+E18 -> 222.06408 | G18: =C18-D18+E18/2 -> 209.56408 | H18: =G18*Assumptions!$B$9 -> 26509.857 | I18: =H18*Assumptions!$B$11 -> 265.09857 | J18: =H18-I18 -> 26244.758 | K18: =H18*Assumptions!$B$12+G18*Assumptions!$B$13 -> 1017.2241 | L18: =G18*(Assumptions!$B$14+Assumptions!$B$15) -> 3143.4613 | M18: =E18*Assumptions!$B$16 -> 1500 | N18: =SUM(K18:M18) -> 5660.6853 | O18: =J18-N18 -> 20584.073 | P18: =INDEX(Assumptions!$B$30:$D$30,1,B18) -> 15500 | Q18: =Acquisition!C18 -> 0 | R18: =O18-P18-Q18 -> 5084.0728 | S18: =0 -> 0 | T18: =R18-S18 -> 5084.0728 | U18: =U17+T18 -> 85142.65 | V18: =F18*Assumptions!$B$9 -> 28091.107 | W18: =V18*12 -> 337093.28
A19: 18 | B19: =INT((A19-1)/12)+1 -> 2 | C19: =F18 -> 222.06408 | D19: =C19*Assumptions!$B$10 -> 4.4412817 | E19: =Acquisition!B19*1 -> 25 | F19: =C19-D19+E19 -> 242.6228 | G19: =C19-D19+E19/2 -> 230.1228 | H19: =G19*Assumptions!$B$9 -> 29110.535 | I19: =H19*Assumptions!$B$11 -> 291.10535 | J19: =H19-I19 -> 28819.429 | K19: =H19*Assumptions!$B$12+G19*Assumptions!$B$13 -> 1117.0161 | L19: =G19*(Assumptions!$B$14+Assumptions!$B$15) -> 3451.842 | M19: =E19*Assumptions!$B$16 -> 1500 | N19: =SUM(K19:M19) -> 6068.8581 | O19: =J19-N19 -> 22750.571 | P19: =INDEX(Assumptions!$B$30:$D$30,1,B19) -> 15500 | Q19: =Acquisition!C19 -> 0 | R19: =O19-P19-Q19 -> 7250.571 | S19: =0 -> 0 | T19: =R19-S19 -> 7250.571 | U19: =U18+T19 -> 92393.221 | V19: =F19*Assumptions!$B$9 -> 30691.785 | W19: =V19*12 -> 368301.41
A20: 19 | B20: =INT((A20-1)/12)+1 -> 2 | C20: =F19 -> 242.6228 | D20: =C20*Assumptions!$B$10 -> 4.852456 | E20: =Acquisition!B20*1 -> 25 | F20: =C20-D20+E20 -> 262.77035 | G20: =C20-D20+E20/2 -> 250.27035 | H20: =G20*Assumptions!$B$9 -> 31659.199 | I20: =H20*Assumptions!$B$11 -> 316.59199 | J20: =H20-I20 -> 31342.607 | K20: =H20*Assumptions!$B$12+G20*Assumptions!$B$13 -> 1214.8123 | L20: =G20*(Assumptions!$B$14+Assumptions!$B$15) -> 3754.0552 | M20: =E20*Assumptions!$B$16 -> 1500 | N20: =SUM(K20:M20) -> 6468.8675 | O20: =J20-N20 -> 24873.739 | P20: =INDEX(Assumptions!$B$30:$D$30,1,B20) -> 15500 | Q20: =Acquisition!C20 -> 0 | R20: =O20-P20-Q20 -> 9373.7394 | S20: =0 -> 0 | T20: =R20-S20 -> 9373.7394 | U20: =U19+T20 -> 101766.96 | V20: =F20*Assumptions!$B$9 -> 33240.449 | W20: =V20*12 -> 398885.39
A21: 20 | B21: =INT((A21-1)/12)+1 -> 2 | C21: =F20 -> 262.77035 | D21: =C21*Assumptions!$B$10 -> 5.2554069 | E21: =Acquisition!B21*1 -> 25 | F21: =C21-D21+E21 -> 282.51494 | G21: =C21-D21+E21/2 -> 270.01494 | H21: =G21*Assumptions!$B$9 -> 34156.89 | I21: =H21*Assumptions!$B$11 -> 341.5689 | J21: =H21-I21 -> 33815.321 | K21: =H21*Assumptions!$B$12+G21*Assumptions!$B$13 -> 1310.6525 | L21: =G21*(Assumptions!$B$14+Assumptions!$B$15) -> 4050.2241 | M21: =E21*Assumptions!$B$16 -> 1500 | N21: =SUM(K21:M21) -> 6860.8766 | O21: =J21-N21 -> 26954.444 | P21: =INDEX(Assumptions!$B$30:$D$30,1,B21) -> 15500 | Q21: =Acquisition!C21 -> 0 | R21: =O21-P21-Q21 -> 11454.444 | S21: =0 -> 0 | T21: =R21-S21 -> 11454.444 | U21: =U20+T21 -> 113221.4 | V21: =F21*Assumptions!$B$9 -> 35738.14 | W21: =V21*12 -> 428857.68
A22: 21 | B22: =INT((A22-1)/12)+1 -> 2 | C22: =F21 -> 282.51494 | D22: =C22*Assumptions!$B$10 -> 5.6502988 | E22: =Acquisition!B22*1 -> 25 | F22: =C22-D22+E22 -> 301.86464 | G22: =C22-D22+E22/2 -> 289.36464 | H22: =G22*Assumptions!$B$9 -> 36604.627 | I22: =H22*Assumptions!$B$11 -> 366.04627 | J22: =H22-I22 -> 36238.581 | K22: =H22*Assumptions!$B$12+G22*Assumptions!$B$13 -> 1404.576 | L22: =G22*(Assumptions!$B$14+Assumptions!$B$15) -> 4340.4696 | M22: =E22*Assumptions!$B$16 -> 1500 | N22: =SUM(K22:M22) -> 7245.0456 | O22: =J22-N22 -> 28993.535 | P22: =INDEX(Assumptions!$B$30:$D$30,1,B22) -> 15500 | Q22: =Acquisition!C22 -> 0 | R22: =O22-P22-Q22 -> 13493.535 | S22: =0 -> 0 | T22: =R22-S22 -> 13493.535 | U22: =U21+T22 -> 126714.94 | V22: =F22*Assumptions!$B$9 -> 38185.877 | W22: =V22*12 -> 458230.52
A23: 22 | B23: =INT((A23-1)/12)+1 -> 2 | C23: =F22 -> 301.86464 | D23: =C23*Assumptions!$B$10 -> 6.0372928 | E23: =Acquisition!B23*1 -> 25 | F23: =C23-D23+E23 -> 320.82735 | G23: =C23-D23+E23/2 -> 308.32735 | H23: =G23*Assumptions!$B$9 -> 39003.41 | I23: =H23*Assumptions!$B$11 -> 390.0341 | J23: =H23-I23 -> 38613.375 | K23: =H23*Assumptions!$B$12+G23*Assumptions!$B$13 -> 1496.6209 | L23: =G23*(Assumptions!$B$14+Assumptions!$B$15) -> 4624.9102 | M23: =E23*Assumptions!$B$16 -> 1500 | N23: =SUM(K23:M23) -> 7621.5312 | O23: =J23-N23 -> 30991.844 | P23: =INDEX(Assumptions!$B$30:$D$30,1,B23) -> 15500 | Q23: =Acquisition!C23 -> 0 | R23: =O23-P23-Q23 -> 15491.844 | S23: =0 -> 0 | T23: =R23-S23 -> 15491.844 | U23: =U22+T23 -> 142206.78 | V23: =F23*Assumptions!$B$9 -> 40584.66 | W23: =V23*12 -> 487015.91
A24: 23 | B24: =INT((A24-1)/12)+1 -> 2 | C24: =F23 -> 320.82735 | D24: =C24*Assumptions!$B$10 -> 6.416547 | E24: =Acquisition!B24*1 -> 25 | F24: =C24-D24+E24 -> 339.4108 | G24: =C24-D24+E24/2 -> 326.9108 | H24: =G24*Assumptions!$B$9 -> 41354.216 | I24: =H24*Assumptions!$B$11 -> 413.54216 | J24: =H24-I24 -> 40940.674 | K24: =H24*Assumptions!$B$12+G24*Assumptions!$B$13 -> 1586.825 | L24: =G24*(Assumptions!$B$14+Assumptions!$B$15) -> 4903.662 | M24: =E24*Assumptions!$B$16 -> 1500 | N24: =SUM(K24:M24) -> 7990.487 | O24: =J24-N24 -> 32950.187 | P24: =INDEX(Assumptions!$B$30:$D$30,1,B24) -> 15500 | Q24: =Acquisition!C24 -> 0 | R24: =O24-P24-Q24 -> 17450.187 | S24: =0 -> 0 | T24: =R24-S24 -> 17450.187 | U24: =U23+T24 -> 159656.97 | V24: =F24*Assumptions!$B$9 -> 42935.466 | W24: =V24*12 -> 515225.6
A25: 24 | B25: =INT((A25-1)/12)+1 -> 2 | C25: =F24 -> 339.4108 | D25: =C25*Assumptions!$B$10 -> 6.788216 | E25: =Acquisition!B25*1 -> 25 | F25: =C25-D25+E25 -> 357.62258 | G25: =C25-D25+E25/2 -> 345.12258 | H25: =G25*Assumptions!$B$9 -> 43658.007 | I25: =H25*Assumptions!$B$11 -> 436.58007 | J25: =H25-I25 -> 43221.427 | K25: =H25*Assumptions!$B$12+G25*Assumptions!$B$13 -> 1675.225 | L25: =G25*(Assumptions!$B$14+Assumptions!$B$15) -> 5176.8388 | M25: =E25*Assumptions!$B$16 -> 1500 | N25: =SUM(K25:M25) -> 8352.0638 | O25: =J25-N25 -> 34869.363 | P25: =INDEX(Assumptions!$B$30:$D$30,1,B25) -> 15500 | Q25: =Acquisition!C25 -> 0 | R25: =O25-P25-Q25 -> 19369.363 | S25: =MAX(SUM(R14:R25),0)*Assumptions!$B$17 -> 24185.284 | T25: =R25-S25 -> -4815.9205 | U25: =U24+T25 -> 154841.05 | V25: =F25*Assumptions!$B$9 -> 45239.257 | W25: =V25*12 -> 542871.08
A26: 25 | B26: =INT((A26-1)/12)+1 -> 3 | C26: =F25 -> 357.62258 | D26: =C26*Assumptions!$B$10 -> 7.1524517 | E26: =Acquisition!B26*1 -> 40 | F26: =C26-D26+E26 -> 390.47013 | G26: =C26-D26+E26/2 -> 370.47013 | H26: =G26*Assumptions!$B$9 -> 46864.472 | I26: =H26*Assumptions!$B$11 -> 468.64472 | J26: =H26-I26 -> 46395.827 | K26: =H26*Assumptions!$B$12+G26*Assumptions!$B$13 -> 1798.262 | L26: =G26*(Assumptions!$B$14+Assumptions!$B$15) -> 5557.052 | M26: =E26*Assumptions!$B$16 -> 2400 | N26: =SUM(K26:M26) -> 9755.314 | O26: =J26-N26 -> 36640.513 | P26: =INDEX(Assumptions!$B$30:$D$30,1,B26) -> 22000 | Q26: =Acquisition!C26 -> 0 | R26: =O26-P26-Q26 -> 14640.513 | S26: =0 -> 0 | T26: =R26-S26 -> 14640.513 | U26: =U25+T26 -> 169481.56 | V26: =F26*Assumptions!$B$9 -> 49394.472 | W26: =V26*12 -> 592733.66
A27: 26 | B27: =INT((A27-1)/12)+1 -> 3 | C27: =F26 -> 390.47013 | D27: =C27*Assumptions!$B$10 -> 7.8094027 | E27: =Acquisition!B27*1 -> 40 | F27: =C27-D27+E27 -> 422.66073 | G27: =C27-D27+E27/2 -> 402.66073 | H27: =G27*Assumptions!$B$9 -> 50936.582 | I27: =H27*Assumptions!$B$11 -> 509.36582 | J27: =H27-I27 -> 50427.217 | K27: =H27*Assumptions!$B$12+G27*Assumptions!$B$13 -> 1954.5152 | L27: =G27*(Assumptions!$B$14+Assumptions!$B$15) -> 6039.911 | M27: =E27*Assumptions!$B$16 -> 2400 | N27: =SUM(K27:M27) -> 10394.426 | O27: =J27-N27 -> 40032.79 | P27: =INDEX(Assumptions!$B$30:$D$30,1,B27) -> 22000 | Q27: =Acquisition!C27 -> 0 | R27: =O27-P27-Q27 -> 18032.79 | S27: =0 -> 0 | T27: =R27-S27 -> 18032.79 | U27: =U26+T27 -> 187514.35 | V27: =F27*Assumptions!$B$9 -> 53466.582 | W27: =V27*12 -> 641598.99
A28: 27 | B28: =INT((A28-1)/12)+1 -> 3 | C28: =F27 -> 422.66073 | D28: =C28*Assumptions!$B$10 -> 8.4532146 | E28: =Acquisition!B28*1 -> 40 | F28: =C28-D28+E28 -> 454.20752 | G28: =C28-D28+E28/2 -> 434.20752 | H28: =G28*Assumptions!$B$9 -> 54927.251 | I28: =H28*Assumptions!$B$11 -> 549.27251 | J28: =H28-I28 -> 54377.978 | K28: =H28*Assumptions!$B$12+G28*Assumptions!$B$13 -> 2107.6433 | L28: =G28*(Assumptions!$B$14+Assumptions!$B$15) -> 6513.1127 | M28: =E28*Assumptions!$B$16 -> 2400 | N28: =SUM(K28:M28) -> 11020.756 | O28: =J28-N28 -> 43357.222 | P28: =INDEX(Assumptions!$B$30:$D$30,1,B28) -> 22000 | Q28: =Acquisition!C28 -> 0 | R28: =O28-P28-Q28 -> 21357.222 | S28: =0 -> 0 | T28: =R28-S28 -> 21357.222 | U28: =U27+T28 -> 208871.58 | V28: =F28*Assumptions!$B$9 -> 57457.251 | W28: =V28*12 -> 689487.01
A29: 28 | B29: =INT((A29-1)/12)+1 -> 3 | C29: =F28 -> 454.20752 | D29: =C29*Assumptions!$B$10 -> 9.0841503 | E29: =Acquisition!B29*1 -> 40 | F29: =C29-D29+E29 -> 485.12337 | G29: =C29-D29+E29/2 -> 465.12337 | H29: =G29*Assumptions!$B$9 -> 58838.106 | I29: =H29*Assumptions!$B$11 -> 588.38106 | J29: =H29-I29 -> 58249.725 | K29: =H29*Assumptions!$B$12+G29*Assumptions!$B$13 -> 2257.7088 | L29: =G29*(Assumptions!$B$14+Assumptions!$B$15) -> 6976.8505 | M29: =E29*Assumptions!$B$16 -> 2400 | N29: =SUM(K29:M29) -> 11634.559 | O29: =J29-N29 -> 46615.165 | P29: =INDEX(Assumptions!$B$30:$D$30,1,B29) -> 22000 | Q29: =Acquisition!C29 -> 0 | R29: =O29-P29-Q29 -> 24615.165 | S29: =0 -> 0 | T29: =R29-S29 -> 24615.165 | U29: =U28+T29 -> 233486.74 | V29: =F29*Assumptions!$B$9 -> 61368.106 | W29: =V29*12 -> 736417.27
A30: 29 | B30: =INT((A30-1)/12)+1 -> 3 | C30: =F29 -> 485.12337 | D30: =C30*Assumptions!$B$10 -> 9.7024673 | E30: =Acquisition!B30*1 -> 40 | F30: =C30-D30+E30 -> 515.4209 | G30: =C30-D30+E30/2 -> 495.4209 | H30: =G30*Assumptions!$B$9 -> 62670.744 | I30: =H30*Assumptions!$B$11 -> 626.70744 | J30: =H30-I30 -> 62044.036 | K30: =H30*Assumptions!$B$12+G30*Assumptions!$B$13 -> 2404.773 | L30: =G30*(Assumptions!$B$14+Assumptions!$B$15) -> 7431.3135 | M30: =E30*Assumptions!$B$16 -> 2400 | N30: =SUM(K30:M30) -> 12236.087 | O30: =J30-N30 -> 49807.95 | P30: =INDEX(Assumptions!$B$30:$D$30,1,B30) -> 22000 | Q30: =Acquisition!C30 -> 0 | R30: =O30-P30-Q30 -> 27807.95 | S30: =0 -> 0 | T30: =R30-S30 -> 27807.95 | U30: =U29+T30 -> 261294.69 | V30: =F30*Assumptions!$B$9 -> 65200.744 | W30: =V30*12 -> 782408.92
A31: 30 | B31: =INT((A31-1)/12)+1 -> 3 | C31: =F30 -> 515.4209 | D31: =C31*Assumptions!$B$10 -> 10.308418 | E31: =Acquisition!B31*1 -> 40 | F31: =C31-D31+E31 -> 545.11248 | G31: =C31-D31+E31/2 -> 525.11248 | H31: =G31*Assumptions!$B$9 -> 66426.729 | I31: =H31*Assumptions!$B$11 -> 664.26729 | J31: =H31-I31 -> 65762.461 | K31: =H31*Assumptions!$B$12+G31*Assumptions!$B$13 -> 2548.896 | L31: =G31*(Assumptions!$B$14+Assumptions!$B$15) -> 7876.6872 | M31: =E31*Assumptions!$B$16 -> 2400 | N31: =SUM(K31:M31) -> 12825.583 | O31: =J31-N31 -> 52936.878 | P31: =INDEX(Assumptions!$B$30:$D$30,1,B31) -> 22000 | Q31: =Acquisition!C31 -> 0 | R31: =O31-P31-Q31 -> 30936.878 | S31: =0 -> 0 | T31: =R31-S31 -> 30936.878 | U31: =U30+T31 -> 292231.57 | V31: =F31*Assumptions!$B$9 -> 68956.729 | W31: =V31*12 -> 827480.75
A32: 31 | B32: =INT((A32-1)/12)+1 -> 3 | C32: =F31 -> 545.11248 | D32: =C32*Assumptions!$B$10 -> 10.90225 | E32: =Acquisition!B32*1 -> 40 | F32: =C32-D32+E32 -> 574.21023 | G32: =C32-D32+E32/2 -> 554.21023 | H32: =G32*Assumptions!$B$9 -> 70107.594 | I32: =H32*Assumptions!$B$11 -> 701.07594 | J32: =H32-I32 -> 69406.518 | K32: =H32*Assumptions!$B$12+G32*Assumptions!$B$13 -> 2690.1365 | L32: =G32*(Assumptions!$B$14+Assumptions!$B$15) -> 8313.1535 | M32: =E32*Assumptions!$B$16 -> 2400 | N32: =SUM(K32:M32) -> 13403.29 | O32: =J32-N32 -> 56003.228 | P32: =INDEX(Assumptions!$B$30:$D$30,1,B32) -> 22000 | Q32: =Acquisition!C32 -> 0 | R32: =O32-P32-Q32 -> 34003.228 | S32: =0 -> 0 | T32: =R32-S32 -> 34003.228 | U32: =U31+T32 -> 326234.8 | V32: =F32*Assumptions!$B$9 -> 72637.594 | W32: =V32*12 -> 871651.13
A33: 32 | B33: =INT((A33-1)/12)+1 -> 3 | C33: =F32 -> 574.21023 | D33: =C33*Assumptions!$B$10 -> 11.484205 | E33: =Acquisition!B33*1 -> 40 | F33: =C33-D33+E33 -> 602.72603 | G33: =C33-D33+E33/2 -> 582.72603 | H33: =G33*Assumptions!$B$9 -> 73714.842 | I33: =H33*Assumptions!$B$11 -> 737.14842 | J33: =H33-I33 -> 72977.694 | K33: =H33*Assumptions!$B$12+G33*Assumptions!$B$13 -> 2828.5521 | L33: =G33*(Assumptions!$B$14+Assumptions!$B$15) -> 8740.8904 | M33: =E33*Assumptions!$B$16 -> 2400 | N33: =SUM(K33:M33) -> 13969.443 | O33: =J33-N33 -> 59008.251 | P33: =INDEX(Assumptions!$B$30:$D$30,1,B33) -> 22000 | Q33: =Acquisition!C33 -> 0 | R33: =O33-P33-Q33 -> 37008.251 | S33: =0 -> 0 | T33: =R33-S33 -> 37008.251 | U33: =U32+T33 -> 363243.05 | V33: =F33*Assumptions!$B$9 -> 76244.842 | W33: =V33*12 -> 914938.11
A34: 33 | B34: =INT((A34-1)/12)+1 -> 3 | C34: =F33 -> 602.72603 | D34: =C34*Assumptions!$B$10 -> 12.054521 | E34: =Acquisition!B34*1 -> 40 | F34: =C34-D34+E34 -> 630.67151 | G34: =C34-D34+E34/2 -> 610.67151 | H34: =G34*Assumptions!$B$9 -> 77249.945 | I34: =H34*Assumptions!$B$11 -> 772.49945 | J34: =H34-I34 -> 76477.446 | K34: =H34*Assumptions!$B$12+G34*Assumptions!$B$13 -> 2964.1995 | L34: =G34*(Assumptions!$B$14+Assumptions!$B$15) -> 9160.0726 | M34: =E34*Assumptions!$B$16 -> 2400 | N34: =SUM(K34:M34) -> 14524.272 | O34: =J34-N34 -> 61953.174 | P34: =INDEX(Assumptions!$B$30:$D$30,1,B34) -> 22000 | Q34: =Acquisition!C34 -> 0 | R34: =O34-P34-Q34 -> 39953.174 | S34: =0 -> 0 | T34: =R34-S34 -> 39953.174 | U34: =U33+T34 -> 403196.22 | V34: =F34*Assumptions!$B$9 -> 79779.945 | W34: =V34*12 -> 957359.35
A35: 34 | B35: =INT((A35-1)/12)+1 -> 3 | C35: =F34 -> 630.67151 | D35: =C35*Assumptions!$B$10 -> 12.61343 | E35: =Acquisition!B35*1 -> 40 | F35: =C35-D35+E35 -> 658.05808 | G35: =C35-D35+E35/2 -> 638.05808 | H35: =G35*Assumptions!$B$9 -> 80714.347 | I35: =H35*Assumptions!$B$11 -> 807.14347 | J35: =H35-I35 -> 79907.203 | K35: =H35*Assumptions!$B$12+G35*Assumptions!$B$13 -> 3097.1339 | L35: =G35*(Assumptions!$B$14+Assumptions!$B$15) -> 9570.8711 | M35: =E35*Assumptions!$B$16 -> 2400 | N35: =SUM(K35:M35) -> 15068.005 | O35: =J35-N35 -> 64839.198 | P35: =INDEX(Assumptions!$B$30:$D$30,1,B35) -> 22000 | Q35: =Acquisition!C35 -> 0 | R35: =O35-P35-Q35 -> 42839.198 | S35: =0 -> 0 | T35: =R35-S35 -> 42839.198 | U35: =U34+T35 -> 446035.42 | V35: =F35*Assumptions!$B$9 -> 83244.347 | W35: =V35*12 -> 998932.16
A36: 35 | B36: =INT((A36-1)/12)+1 -> 3 | C36: =F35 -> 658.05808 | D36: =C36*Assumptions!$B$10 -> 13.161162 | E36: =Acquisition!B36*1 -> 40 | F36: =C36-D36+E36 -> 684.89691 | G36: =C36-D36+E36/2 -> 664.89691 | H36: =G36*Assumptions!$B$9 -> 84109.46 | I36: =H36*Assumptions!$B$11 -> 841.0946 | J36: =H36-I36 -> 83268.365 | K36: =H36*Assumptions!$B$12+G36*Assumptions!$B$13 -> 3227.4096 | L36: =G36*(Assumptions!$B$14+Assumptions!$B$15) -> 9973.4537 | M36: =E36*Assumptions!$B$16 -> 2400 | N36: =SUM(K36:M36) -> 15600.863 | O36: =J36-N36 -> 67667.502 | P36: =INDEX(Assumptions!$B$30:$D$30,1,B36) -> 22000 | Q36: =Acquisition!C36 -> 0 | R36: =O36-P36-Q36 -> 45667.502 | S36: =0 -> 0 | T36: =R36-S36 -> 45667.502 | U36: =U35+T36 -> 491702.92 | V36: =F36*Assumptions!$B$9 -> 86639.46 | W36: =V36*12 -> 1039673.5
A37: 36 | B37: =INT((A37-1)/12)+1 -> 3 | C37: =F36 -> 684.89691 | D37: =C37*Assumptions!$B$10 -> 13.697938 | E37: =Acquisition!B37*1 -> 40 | F37: =C37-D37+E37 -> 711.19898 | G37: =C37-D37+E37/2 -> 691.19898 | H37: =G37*Assumptions!$B$9 -> 87436.67 | I37: =H37*Assumptions!$B$11 -> 874.3667 | J37: =H37-I37 -> 86562.304 | K37: =H37*Assumptions!$B$12+G37*Assumptions!$B$13 -> 3355.0798 | L37: =G37*(Assumptions!$B$14+Assumptions!$B$15) -> 10367.985 | M37: =E37*Assumptions!$B$16 -> 2400 | N37: =SUM(K37:M37) -> 16123.064 | O37: =J37-N37 -> 70439.239 | P37: =INDEX(Assumptions!$B$30:$D$30,1,B37) -> 22000 | Q37: =Acquisition!C37 -> 0 | R37: =O37-P37-Q37 -> 48439.239 | S37: =MAX(SUM(R26:R37),0)*Assumptions!$B$17 -> 96325.278 | T37: =R37-S37 -> -47886.039 | U37: =U36+T37 -> 443816.88 | V37: =F37*Assumptions!$B$9 -> 89966.67 | W37: =V37*12 -> 1079600

Sheet Downside
A1: Month | B1: Year | C1: Opening paid | D1: Churned | E1: New paid | F1: Ending paid | G1: Billed equivalent | H1: Gross charges | I1: Credits/refunds | J1: Net revenue | K1: Payment fees | L1: Service delivery | M1: Onboarding | N1: Total COGS | O1: Gross profit | P1: Fixed opex | Q1: Launch costs | R1: Operating profit | S1: Tax reserve | T1: Net income | U1: Ending cash | V1: Exit MRR | W1: Exit ARR
A2: 1 | B2: =INT((A2-1)/12)+1 -> 1 | C2: =0 -> 0 | D2: =C2*Assumptions!$B$20 -> 0 | E2: =Acquisition!B2*Assumptions!$B$19 -> 0 | F2: =C2-D2+E2 -> 0 | G2: =C2-D2+E2/2 -> 0 | H2: =G2*Assumptions!$B$9*Assumptions!$B$21 -> 0 | I2: =H2*Assumptions!$B$11 -> 0 | J2: =H2-I2 -> 0 | K2: =H2*Assumptions!$B$12+G2*Assumptions!$B$13 -> 0 | L2: =G2*(Assumptions!$B$14+Assumptions!$B$15) -> 0 | M2: =E2*Assumptions!$B$16 -> 0 | N2: =SUM(K2:M2) -> 0 | O2: =J2-N2 -> 0 | P2: =INDEX(Assumptions!$B$30:$D$30,1,B2) -> 9500 | Q2: =Acquisition!C2 -> 10000 | R2: =O2-P2-Q2 -> -19500 | S2: =0 -> 0 | T2: =R2-S2 -> -19500 | U2: =Assumptions!$B$2+T2 -> 155500 | V2: =F2*Assumptions!$B$9*Assumptions!$B$21 -> 0 | W2: =V2*12 -> 0
A3: 2 | B3: =INT((A3-1)/12)+1 -> 1 | C3: =F2 -> 0 | D3: =C3*Assumptions!$B$20 -> 0 | E3: =Acquisition!B3*Assumptions!$B$19 -> 0 | F3: =C3-D3+E3 -> 0 | G3: =C3-D3+E3/2 -> 0 | H3: =G3*Assumptions!$B$9*Assumptions!$B$21 -> 0 | I3: =H3*Assumptions!$B$11 -> 0 | J3: =H3-I3 -> 0 | K3: =H3*Assumptions!$B$12+G3*Assumptions!$B$13 -> 0 | L3: =G3*(Assumptions!$B$14+Assumptions!$B$15) -> 0 | M3: =E3*Assumptions!$B$16 -> 0 | N3: =SUM(K3:M3) -> 0 | O3: =J3-N3 -> 0 | P3: =INDEX(Assumptions!$B$30:$D$30,1,B3) -> 9500 | Q3: =Acquisition!C3 -> 5000 | R3: =O3-P3-Q3 -> -14500 | S3: =0 -> 0 | T3: =R3-S3 -> -14500 | U3: =U2+T3 -> 141000 | V3: =F3*Assumptions!$B$9*Assumptions!$B$21 -> 0 | W3: =V3*12 -> 0
A4: 3 | B4: =INT((A4-1)/12)+1 -> 1 | C4: =F3 -> 0 | D4: =C4*Assumptions!$B$20 -> 0 | E4: =Acquisition!B4*Assumptions!$B$19 -> 1.8 | F4: =C4-D4+E4 -> 1.8 | G4: =C4-D4+E4/2 -> 0.9 | H4: =G4*Assumptions!$B$9*Assumptions!$B$21 -> 102.465 | I4: =H4*Assumptions!$B$11 -> 1.02465 | J4: =H4-I4 -> 101.44035 | K4: =H4*Assumptions!$B$12+G4*Assumptions!$B$13 -> 3.95874 | L4: =G4*(Assumptions!$B$14+Assumptions!$B$15) -> 13.5 | M4: =E4*Assumptions!$B$16 -> 108 | N4: =SUM(K4:M4) -> 125.45874 | O4: =J4-N4 -> -24.01839 | P4: =INDEX(Assumptions!$B$30:$D$30,1,B4) -> 9500 | Q4: =Acquisition!C4 -> 0 | R4: =O4-P4-Q4 -> -9524.0184 | S4: =0 -> 0 | T4: =R4-S4 -> -9524.0184 | U4: =U3+T4 -> 131475.98 | V4: =F4*Assumptions!$B$9*Assumptions!$B$21 -> 204.93 | W4: =V4*12 -> 2459.16
A5: 4 | B5: =INT((A5-1)/12)+1 -> 1 | C5: =F4 -> 1.8 | D5: =C5*Assumptions!$B$20 -> 0.063 | E5: =Acquisition!B5*Assumptions!$B$19 -> 3 | F5: =C5-D5+E5 -> 4.737 | G5: =C5-D5+E5/2 -> 3.237 | H5: =G5*Assumptions!$B$9*Assumptions!$B$21 -> 368.53245 | I5: =H5*Assumptions!$B$11 -> 3.6853245 | J5: =H5-I5 -> 364.84713 | K5: =H5*Assumptions!$B$12+G5*Assumptions!$B$13 -> 14.238268 | L5: =G5*(Assumptions!$B$14+Assumptions!$B$15) -> 48.555 | M5: =E5*Assumptions!$B$16 -> 180 | N5: =SUM(K5:M5) -> 242.79327 | O5: =J5-N5 -> 122.05386 | P5: =INDEX(Assumptions!$B$30:$D$30,1,B5) -> 9500 | Q5: =Acquisition!C5 -> 0 | R5: =O5-P5-Q5 -> -9377.9461 | S5: =0 -> 0 | T5: =R5-S5 -> -9377.9461 | U5: =U4+T5 -> 122098.04 | V5: =F5*Assumptions!$B$9*Assumptions!$B$21 -> 539.30745 | W5: =V5*12 -> 6471.6894
A6: 5 | B6: =INT((A6-1)/12)+1 -> 1 | C6: =F5 -> 4.737 | D6: =C6*Assumptions!$B$20 -> 0.165795 | E6: =Acquisition!B6*Assumptions!$B$19 -> 4.2 | F6: =C6-D6+E6 -> 8.771205 | G6: =C6-D6+E6/2 -> 6.671205 | H6: =G6*Assumptions!$B$9*Assumptions!$B$21 -> 759.51669 | I6: =H6*Assumptions!$B$11 -> 7.5951669 | J6: =H6-I6 -> 751.92152 | K6: =H6*Assumptions!$B$12+G6*Assumptions!$B$13 -> 29.343962 | L6: =G6*(Assumptions!$B$14+Assumptions!$B$15) -> 100.06808 | M6: =E6*Assumptions!$B$16 -> 252 | N6: =SUM(K6:M6) -> 381.41204 | O6: =J6-N6 -> 370.50949 | P6: =INDEX(Assumptions!$B$30:$D$30,1,B6) -> 9500 | Q6: =Acquisition!C6 -> 0 | R6: =O6-P6-Q6 -> -9129.4905 | S6: =0 -> 0 | T6: =R6-S6 -> -9129.4905 | U6: =U5+T6 -> 112968.54 | V6: =F6*Assumptions!$B$9*Assumptions!$B$21 -> 998.60169 | W6: =V6*12 -> 11983.22
A7: 6 | B7: =INT((A7-1)/12)+1 -> 1 | C7: =F6 -> 8.771205 | D7: =C7*Assumptions!$B$20 -> 0.30699218 | E7: =Acquisition!B7*Assumptions!$B$19 -> 5.4 | F7: =C7-D7+E7 -> 13.864213 | G7: =C7-D7+E7/2 -> 11.164213 | H7: =G7*Assumptions!$B$9*Assumptions!$B$21 -> 1271.0456 | I7: =H7*Assumptions!$B$11 -> 12.710456 | J7: =H7-I7 -> 1258.3352 | K7: =H7*Assumptions!$B$12+G7*Assumptions!$B$13 -> 49.106907 | L7: =G7*(Assumptions!$B$14+Assumptions!$B$15) -> 167.46319 | M7: =E7*Assumptions!$B$16 -> 324 | N7: =SUM(K7:M7) -> 540.5701 | O7: =J7-N7 -> 717.76507 | P7: =INDEX(Assumptions!$B$30:$D$30,1,B7) -> 9500 | Q7: =Acquisition!C7 -> 0 | R7: =O7-P7-Q7 -> -8782.2349 | S7: =0 -> 0 | T7: =R7-S7 -> -8782.2349 | U7: =U6+T7 -> 104186.31 | V7: =F7*Assumptions!$B$9*Assumptions!$B$21 -> 1578.4406 | W7: =V7*12 -> 18941.288
A8: 7 | B8: =INT((A8-1)/12)+1 -> 1 | C8: =F7 -> 13.864213 | D8: =C8*Assumptions!$B$20 -> 0.48524745 | E8: =Acquisition!B8*Assumptions!$B$19 -> 6.6 | F8: =C8-D8+E8 -> 19.978965 | G8: =C8-D8+E8/2 -> 16.678965 | H8: =G8*Assumptions!$B$9*Assumptions!$B$21 -> 1898.9002 | I8: =H8*Assumptions!$B$11 -> 18.989002 | J8: =H8-I8 -> 1879.9112 | K8: =H8*Assumptions!$B$12+G8*Assumptions!$B$13 -> 73.364097 | L8: =G8*(Assumptions!$B$14+Assumptions!$B$15) -> 250.18448 | M8: =E8*Assumptions!$B$16 -> 396 | N8: =SUM(K8:M8) -> 719.54858 | O8: =J8-N8 -> 1160.3626 | P8: =INDEX(Assumptions!$B$30:$D$30,1,B8) -> 9500 | Q8: =Acquisition!C8 -> 0 | R8: =O8-P8-Q8 -> -8339.6374 | S8: =0 -> 0 | T8: =R8-S8 -> -8339.6374 | U8: =U7+T8 -> 95846.673 | V8: =F8*Assumptions!$B$9*Assumptions!$B$21 -> 2274.6052 | W8: =V8*12 -> 27295.262
A9: 8 | B9: =INT((A9-1)/12)+1 -> 1 | C9: =F8 -> 19.978965 | D9: =C9*Assumptions!$B$20 -> 0.69926379 | E9: =Acquisition!B9*Assumptions!$B$19 -> 7.8 | F9: =C9-D9+E9 -> 27.079702 | G9: =C9-D9+E9/2 -> 23.179702 | H9: =G9*Assumptions!$B$9*Assumptions!$B$21 -> 2639.009 | I9: =H9*Assumptions!$B$11 -> 26.39009 | J9: =H9-I9 -> 2612.6189 | K9: =H9*Assumptions!$B$12+G9*Assumptions!$B$13 -> 101.95824 | L9: =G9*(Assumptions!$B$14+Assumptions!$B$15) -> 347.69552 | M9: =E9*Assumptions!$B$16 -> 468 | N9: =SUM(K9:M9) -> 917.65376 | O9: =J9-N9 -> 1694.9652 | P9: =INDEX(Assumptions!$B$30:$D$30,1,B9) -> 9500 | Q9: =Acquisition!C9 -> 0 | R9: =O9-P9-Q9 -> -7805.0348 | S9: =0 -> 0 | T9: =R9-S9 -> -7805.0348 | U9: =U8+T9 -> 88041.638 | V9: =F9*Assumptions!$B$9*Assumptions!$B$21 -> 3083.024 | W9: =V9*12 -> 36996.288
A10: 9 | B10: =INT((A10-1)/12)+1 -> 1 | C10: =F9 -> 27.079702 | D10: =C10*Assumptions!$B$20 -> 0.94778956 | E10: =Acquisition!B10*Assumptions!$B$19 -> 9 | F10: =C10-D10+E10 -> 35.131912 | G10: =C10-D10+E10/2 -> 30.631912 | H10: =G10*Assumptions!$B$9*Assumptions!$B$21 -> 3487.4432 | I10: =H10*Assumptions!$B$11 -> 34.874432 | J10: =H10-I10 -> 3452.5688 | K10: =H10*Assumptions!$B$12+G10*Assumptions!$B$13 -> 134.73753 | L10: =G10*(Assumptions!$B$14+Assumptions!$B$15) -> 459.47868 | M10: =E10*Assumptions!$B$16 -> 540 | N10: =SUM(K10:M10) -> 1134.2162 | O10: =J10-N10 -> 2318.3525 | P10: =INDEX(Assumptions!$B$30:$D$30,1,B10) -> 9500 | Q10: =Acquisition!C10 -> 0 | R10: =O10-P10-Q10 -> -7181.6475 | S10: =0 -> 0 | T10: =R10-S10 -> -7181.6475 | U10: =U9+T10 -> 80859.99 | V10: =F10*Assumptions!$B$9*Assumptions!$B$21 -> 3999.7682 | W10: =V10*12 -> 47997.218
A11: 10 | B11: =INT((A11-1)/12)+1 -> 1 | C11: =F10 -> 35.131912 | D11: =C11*Assumptions!$B$20 -> 1.2296169 | E11: =Acquisition!B11*Assumptions!$B$19 -> 10.2 | F11: =C11-D11+E11 -> 44.102295 | G11: =C11-D11+E11/2 -> 39.002295 | H11: =G11*Assumptions!$B$9*Assumptions!$B$21 -> 4440.4113 | I11: =H11*Assumptions!$B$11 -> 44.404113 | J11: =H11-I11 -> 4396.0072 | K11: =H11*Assumptions!$B$12+G11*Assumptions!$B$13 -> 171.5555 | L11: =G11*(Assumptions!$B$14+Assumptions!$B$15) -> 585.03443 | M11: =E11*Assumptions!$B$16 -> 612 | N11: =SUM(K11:M11) -> 1368.5899 | O11: =J11-N11 -> 3027.4173 | P11: =INDEX(Assumptions!$B$30:$D$30,1,B11) -> 9500 | Q11: =Acquisition!C11 -> 0 | R11: =O11-P11-Q11 -> -6472.5827 | S11: =0 -> 0 | T11: =R11-S11 -> -6472.5827 | U11: =U10+T11 -> 74387.408 | V11: =F11*Assumptions!$B$9*Assumptions!$B$21 -> 5021.0463 | W11: =V11*12 -> 60252.556
A12: 11 | B12: =INT((A12-1)/12)+1 -> 1 | C12: =F11 -> 44.102295 | D12: =C12*Assumptions!$B$20 -> 1.5435803 | E12: =Acquisition!B12*Assumptions!$B$19 -> 11.4 | F12: =C12-D12+E12 -> 53.958715 | G12: =C12-D12+E12/2 -> 48.258715 | H12: =G12*Assumptions!$B$9*Assumptions!$B$21 -> 5494.2547 | I12: =H12*Assumptions!$B$11 -> 54.942547 | J12: =H12-I12 -> 5439.3121 | K12: =H12*Assumptions!$B$12+G12*Assumptions!$B$13 -> 212.27078 | L12: =G12*(Assumptions!$B$14+Assumptions!$B$15) -> 723.88072 | M12: =E12*Assumptions!$B$16 -> 684 | N12: =SUM(K12:M12) -> 1620.1515 | O12: =J12-N12 -> 3819.1606 | P12: =INDEX(Assumptions!$B$30:$D$30,1,B12) -> 9500 | Q12: =Acquisition!C12 -> 0 | R12: =O12-P12-Q12 -> -5680.8394 | S12: =0 -> 0 | T12: =R12-S12 -> -5680.8394 | U12: =U11+T12 -> 68706.568 | V12: =F12*Assumptions!$B$9*Assumptions!$B$21 -> 6143.1997 | W12: =V12*12 -> 73718.396
A13: 12 | B13: =INT((A13-1)/12)+1 -> 1 | C13: =F12 -> 53.958715 | D13: =C13*Assumptions!$B$20 -> 1.888555 | E13: =Acquisition!B13*Assumptions!$B$19 -> 12.6 | F13: =C13-D13+E13 -> 64.67016 | G13: =C13-D13+E13/2 -> 58.37016 | H13: =G13*Assumptions!$B$9*Assumptions!$B$21 -> 6645.4427 | I13: =H13*Assumptions!$B$11 -> 66.454427 | J13: =H13-I13 -> 6578.9883 | K13: =H13*Assumptions!$B$12+G13*Assumptions!$B$13 -> 256.74698 | L13: =G13*(Assumptions!$B$14+Assumptions!$B$15) -> 875.5524 | M13: =E13*Assumptions!$B$16 -> 756 | N13: =SUM(K13:M13) -> 1888.2994 | O13: =J13-N13 -> 4690.6889 | P13: =INDEX(Assumptions!$B$30:$D$30,1,B13) -> 9500 | Q13: =Acquisition!C13 -> 0 | R13: =O13-P13-Q13 -> -4809.3111 | S13: =MAX(SUM(R2:R13),0)*Assumptions!$B$17 -> 0 | T13: =R13-S13 -> -4809.3111 | U13: =U12+T13 -> 63897.257 | V13: =F13*Assumptions!$B$9*Assumptions!$B$21 -> 7362.6977 | W13: =V13*12 -> 88352.372
A14: 13 | B14: =INT((A14-1)/12)+1 -> 2 | C14: =F13 -> 64.67016 | D14: =C14*Assumptions!$B$20 -> 2.2634556 | E14: =Acquisition!B14*Assumptions!$B$19 -> 15 | F14: =C14-D14+E14 -> 77.406704 | G14: =C14-D14+E14/2 -> 69.906704 | H14: =G14*Assumptions!$B$9*Assumptions!$B$21 -> 7958.8783 | I14: =H14*Assumptions!$B$11 -> 79.588783 | J14: =H14-I14 -> 7879.2895 | K14: =H14*Assumptions!$B$12+G14*Assumptions!$B$13 -> 307.49163 | L14: =G14*(Assumptions!$B$14+Assumptions!$B$15) -> 1048.6006 | M14: =E14*Assumptions!$B$16 -> 900 | N14: =SUM(K14:M14) -> 2256.0922 | O14: =J14-N14 -> 5623.1973 | P14: =INDEX(Assumptions!$B$30:$D$30,1,B14) -> 15500 | Q14: =Acquisition!C14 -> 0 | R14: =O14-P14-Q14 -> -9876.8027 | S14: =0 -> 0 | T14: =R14-S14 -> -9876.8027 | U14: =U13+T14 -> 54020.454 | V14: =F14*Assumptions!$B$9*Assumptions!$B$21 -> 8812.7533 | W14: =V14*12 -> 105753.04
A15: 14 | B15: =INT((A15-1)/12)+1 -> 2 | C15: =F14 -> 77.406704 | D15: =C15*Assumptions!$B$20 -> 2.7092346 | E15: =Acquisition!B15*Assumptions!$B$19 -> 15 | F15: =C15-D15+E15 -> 89.69747 | G15: =C15-D15+E15/2 -> 82.19747 | H15: =G15*Assumptions!$B$9*Assumptions!$B$21 -> 9358.1819 | I15: =H15*Assumptions!$B$11 -> 93.581819 | J15: =H15-I15 -> 9264.6001 | K15: =H15*Assumptions!$B$12+G15*Assumptions!$B$13 -> 361.55379 | L15: =G15*(Assumptions!$B$14+Assumptions!$B$15) -> 1232.962 | M15: =E15*Assumptions!$B$16 -> 900 | N15: =SUM(K15:M15) -> 2494.5158 | O15: =J15-N15 -> 6770.0843 | P15: =INDEX(Assumptions!$B$30:$D$30,1,B15) -> 15500 | Q15: =Acquisition!C15 -> 0 | R15: =O15-P15-Q15 -> -8729.9157 | S15: =0 -> 0 | T15: =R15-S15 -> -8729.9157 | U15: =U14+T15 -> 45290.539 | V15: =F15*Assumptions!$B$9*Assumptions!$B$21 -> 10212.057 | W15: =V15*12 -> 122544.68
A16: 15 | B16: =INT((A16-1)/12)+1 -> 2 | C16: =F15 -> 89.69747 | D16: =C16*Assumptions!$B$20 -> 3.1394114 | E16: =Acquisition!B16*Assumptions!$B$19 -> 15 | F16: =C16-D16+E16 -> 101.55806 | G16: =C16-D16+E16/2 -> 94.058058 | H16: =G16*Assumptions!$B$9*Assumptions!$B$21 -> 10708.51 | I16: =H16*Assumptions!$B$11 -> 107.0851 | J16: =H16-I16 -> 10601.425 | K16: =H16*Assumptions!$B$12+G16*Assumptions!$B$13 -> 413.72377 | L16: =G16*(Assumptions!$B$14+Assumptions!$B$15) -> 1410.8709 | M16: =E16*Assumptions!$B$16 -> 900 | N16: =SUM(K16:M16) -> 2724.5946 | O16: =J16-N16 -> 7876.8302 | P16: =INDEX(Assumptions!$B$30:$D$30,1,B16) -> 15500 | Q16: =Acquisition!C16 -> 0 | R16: =O16-P16-Q16 -> -7623.1698 | S16: =0 -> 0 | T16: =R16-S16 -> -7623.1698 | U16: =U15+T16 -> 37667.369 | V16: =F16*Assumptions!$B$9*Assumptions!$B$21 -> 11562.385 | W16: =V16*12 -> 138748.62
A17: 16 | B17: =INT((A17-1)/12)+1 -> 2 | C17: =F16 -> 101.55806 | D17: =C17*Assumptions!$B$20 -> 3.554532 | E17: =Acquisition!B17*Assumptions!$B$19 -> 15 | F17: =C17-D17+E17 -> 113.00353 | G17: =C17-D17+E17/2 -> 105.50353 | H17: =G17*Assumptions!$B$9*Assumptions!$B$21 -> 12011.576 | I17: =H17*Assumptions!$B$11 -> 120.11576 | J17: =H17-I17 -> 11891.461 | K17: =H17*Assumptions!$B$12+G17*Assumptions!$B$13 -> 464.06781 | L17: =G17*(Assumptions!$B$14+Assumptions!$B$15) -> 1582.5529 | M17: =E17*Assumptions!$B$16 -> 900 | N17: =SUM(K17:M17) -> 2946.6207 | O17: =J17-N17 -> 8944.84 | P17: =INDEX(Assumptions!$B$30:$D$30,1,B17) -> 15500 | Q17: =Acquisition!C17 -> 0 | R17: =O17-P17-Q17 -> -6555.16 | S17: =0 -> 0 | T17: =R17-S17 -> -6555.16 | U17: =U16+T17 -> 31112.209 | V17: =F17*Assumptions!$B$9*Assumptions!$B$21 -> 12865.451 | W17: =V17*12 -> 154385.42
A18: 17 | B18: =INT((A18-1)/12)+1 -> 2 | C18: =F17 -> 113.00353 | D18: =C18*Assumptions!$B$20 -> 3.9551234 | E18: =Acquisition!B18*Assumptions!$B$19 -> 15 | F18: =C18-D18+E18 -> 124.0484 | G18: =C18-D18+E18/2 -> 116.5484 | H18: =G18*Assumptions!$B$9*Assumptions!$B$21 -> 13269.036 | I18: =H18*Assumptions!$B$11 -> 132.69036 | J18: =H18-I18 -> 13136.345 | K18: =H18*Assumptions!$B$12+G18*Assumptions!$B$13 -> 512.6498 | L18: =G18*(Assumptions!$B$14+Assumptions!$B$15) -> 1748.226 | M18: =E18*Assumptions!$B$16 -> 900 | N18: =SUM(K18:M18) -> 3160.8758 | O18: =J18-N18 -> 9975.4694 | P18: =INDEX(Assumptions!$B$30:$D$30,1,B18) -> 15500 | Q18: =Acquisition!C18 -> 0 | R18: =O18-P18-Q18 -> -5524.5306 | S18: =0 -> 0 | T18: =R18-S18 -> -5524.5306 | U18: =U17+T18 -> 25587.678 | V18: =F18*Assumptions!$B$9*Assumptions!$B$21 -> 14122.911 | W18: =V18*12 -> 169474.93
A19: 18 | B19: =INT((A19-1)/12)+1 -> 2 | C19: =F18 -> 124.0484 | D19: =C19*Assumptions!$B$20 -> 4.3416941 | E19: =Acquisition!B19*Assumptions!$B$19 -> 15 | F19: =C19-D19+E19 -> 134.70671 | G19: =C19-D19+E19/2 -> 127.20671 | H19: =G19*Assumptions!$B$9*Assumptions!$B$21 -> 14482.484 | I19: =H19*Assumptions!$B$11 -> 144.82484 | J19: =H19-I19 -> 14337.659 | K19: =H19*Assumptions!$B$12+G19*Assumptions!$B$13 -> 559.53143 | L19: =G19*(Assumptions!$B$14+Assumptions!$B$15) -> 1908.1006 | M19: =E19*Assumptions!$B$16 -> 900 | N19: =SUM(K19:M19) -> 3367.6321 | O19: =J19-N19 -> 10970.027 | P19: =INDEX(Assumptions!$B$30:$D$30,1,B19) -> 15500 | Q19: =Acquisition!C19 -> 0 | R19: =O19-P19-Q19 -> -4529.9731 | S19: =0 -> 0 | T19: =R19-S19 -> -4529.9731 | U19: =U18+T19 -> 21057.705 | V19: =F19*Assumptions!$B$9*Assumptions!$B$21 -> 15336.359 | W19: =V19*12 -> 184036.31
A20: 19 | B20: =INT((A20-1)/12)+1 -> 2 | C20: =F19 -> 134.70671 | D20: =C20*Assumptions!$B$20 -> 4.7147348 | E20: =Acquisition!B20*Assumptions!$B$19 -> 15 | F20: =C20-D20+E20 -> 144.99197 | G20: =C20-D20+E20/2 -> 137.49197 | H20: =G20*Assumptions!$B$9*Assumptions!$B$21 -> 15653.461 | I20: =H20*Assumptions!$B$11 -> 156.53461 | J20: =H20-I20 -> 15496.927 | K20: =H20*Assumptions!$B$12+G20*Assumptions!$B$13 -> 604.7722 | L20: =G20*(Assumptions!$B$14+Assumptions!$B$15) -> 2062.3796 | M20: =E20*Assumptions!$B$16 -> 900 | N20: =SUM(K20:M20) -> 3567.1518 | O20: =J20-N20 -> 11929.775 | P20: =INDEX(Assumptions!$B$30:$D$30,1,B20) -> 15500 | Q20: =Acquisition!C20 -> 0 | R20: =O20-P20-Q20 -> -3570.2252 | S20: =0 -> 0 | T20: =R20-S20 -> -3570.2252 | U20: =U19+T20 -> 17487.48 | V20: =F20*Assumptions!$B$9*Assumptions!$B$21 -> 16507.336 | W20: =V20*12 -> 198088.03
A21: 20 | B21: =INT((A21-1)/12)+1 -> 2 | C21: =F20 -> 144.99197 | D21: =C21*Assumptions!$B$20 -> 5.0747191 | E21: =Acquisition!B21*Assumptions!$B$19 -> 15 | F21: =C21-D21+E21 -> 154.91725 | G21: =C21-D21+E21/2 -> 147.41725 | H21: =G21*Assumptions!$B$9*Assumptions!$B$21 -> 16783.454 | I21: =H21*Assumptions!$B$11 -> 167.83454 | J21: =H21-I21 -> 16615.62 | K21: =H21*Assumptions!$B$12+G21*Assumptions!$B$13 -> 648.42954 | L21: =G21*(Assumptions!$B$14+Assumptions!$B$15) -> 2211.2588 | M21: =E21*Assumptions!$B$16 -> 900 | N21: =SUM(K21:M21) -> 3759.6884 | O21: =J21-N21 -> 12855.932 | P21: =INDEX(Assumptions!$B$30:$D$30,1,B21) -> 15500 | Q21: =Acquisition!C21 -> 0 | R21: =O21-P21-Q21 -> -2644.0685 | S21: =0 -> 0 | T21: =R21-S21 -> -2644.0685 | U21: =U20+T21 -> 14843.412 | V21: =F21*Assumptions!$B$9*Assumptions!$B$21 -> 17637.329 | W21: =V21*12 -> 211647.95
A22: 21 | B22: =INT((A22-1)/12)+1 -> 2 | C22: =F21 -> 154.91725 | D22: =C22*Assumptions!$B$20 -> 5.4221039 | E22: =Acquisition!B22*Assumptions!$B$19 -> 15 | F22: =C22-D22+E22 -> 164.49515 | G22: =C22-D22+E22/2 -> 156.99515 | H22: =G22*Assumptions!$B$9*Assumptions!$B$21 -> 17873.898 | I22: =H22*Assumptions!$B$11 -> 178.73898 | J22: =H22-I22 -> 17695.159 | K22: =H22*Assumptions!$B$12+G22*Assumptions!$B$13 -> 690.55887 | L22: =G22*(Assumptions!$B$14+Assumptions!$B$15) -> 2354.9273 | M22: =E22*Assumptions!$B$16 -> 900 | N22: =SUM(K22:M22) -> 3945.4861 | O22: =J22-N22 -> 13749.673 | P22: =INDEX(Assumptions!$B$30:$D$30,1,B22) -> 15500 | Q22: =Acquisition!C22 -> 0 | R22: =O22-P22-Q22 -> -1750.3272 | S22: =0 -> 0 | T22: =R22-S22 -> -1750.3272 | U22: =U21+T22 -> 13093.084 | V22: =F22*Assumptions!$B$9*Assumptions!$B$21 -> 18727.773 | W22: =V22*12 -> 224733.27
A23: 22 | B23: =INT((A23-1)/12)+1 -> 2 | C23: =F22 -> 164.49515 | D23: =C23*Assumptions!$B$20 -> 5.7573303 | E23: =Acquisition!B23*Assumptions!$B$19 -> 15 | F23: =C23-D23+E23 -> 173.73782 | G23: =C23-D23+E23/2 -> 166.23782 | H23: =G23*Assumptions!$B$9*Assumptions!$B$21 -> 18926.176 | I23: =H23*Assumptions!$B$11 -> 189.26176 | J23: =H23-I23 -> 18736.914 | K23: =H23*Assumptions!$B$12+G23*Assumptions!$B$13 -> 731.21368 | L23: =G23*(Assumptions!$B$14+Assumptions!$B$15) -> 2493.5673 | M23: =E23*Assumptions!$B$16 -> 900 | N23: =SUM(K23:M23) -> 4124.781 | O23: =J23-N23 -> 14612.133 | P23: =INDEX(Assumptions!$B$30:$D$30,1,B23) -> 15500 | Q23: =Acquisition!C23 -> 0 | R23: =O23-P23-Q23 -> -887.86688 | S23: =0 -> 0 | T23: =R23-S23 -> -887.86688 | U23: =U22+T23 -> 12205.217 | V23: =F23*Assumptions!$B$9*Assumptions!$B$21 -> 19780.051 | W23: =V23*12 -> 237360.61
A24: 23 | B24: =INT((A24-1)/12)+1 -> 2 | C24: =F23 -> 173.73782 | D24: =C24*Assumptions!$B$20 -> 6.0808237 | E24: =Acquisition!B24*Assumptions!$B$19 -> 15 | F24: =C24-D24+E24 -> 182.657 | G24: =C24-D24+E24/2 -> 175.157 | H24: =G24*Assumptions!$B$9*Assumptions!$B$21 -> 19941.624 | I24: =H24*Assumptions!$B$11 -> 199.41624 | J24: =H24-I24 -> 19742.208 | K24: =H24*Assumptions!$B$12+G24*Assumptions!$B$13 -> 770.44557 | L24: =G24*(Assumptions!$B$14+Assumptions!$B$15) -> 2627.355 | M24: =E24*Assumptions!$B$16 -> 900 | N24: =SUM(K24:M24) -> 4297.8005 | O24: =J24-N24 -> 15444.407 | P24: =INDEX(Assumptions!$B$30:$D$30,1,B24) -> 15500 | Q24: =Acquisition!C24 -> 0 | R24: =O24-P24-Q24 -> -55.592676 | S24: =0 -> 0 | T24: =R24-S24 -> -55.592676 | U24: =U23+T24 -> 12149.625 | V24: =F24*Assumptions!$B$9*Assumptions!$B$21 -> 20795.499 | W24: =V24*12 -> 249545.99
A25: 24 | B25: =INT((A25-1)/12)+1 -> 2 | C25: =F24 -> 182.657 | D25: =C25*Assumptions!$B$20 -> 6.3929949 | E25: =Acquisition!B25*Assumptions!$B$19 -> 15 | F25: =C25-D25+E25 -> 191.264 | G25: =C25-D25+E25/2 -> 183.764 | H25: =G25*Assumptions!$B$9*Assumptions!$B$21 -> 20921.532 | I25: =H25*Assumptions!$B$11 -> 209.21532 | J25: =H25-I25 -> 20712.316 | K25: =H25*Assumptions!$B$12+G25*Assumptions!$B$13 -> 808.30434 | L25: =G25*(Assumptions!$B$14+Assumptions!$B$15) -> 2756.46 | M25: =E25*Assumptions!$B$16 -> 900 | N25: =SUM(K25:M25) -> 4464.7644 | O25: =J25-N25 -> 16247.552 | P25: =INDEX(Assumptions!$B$30:$D$30,1,B25) -> 15500 | Q25: =Acquisition!C25 -> 0 | R25: =O25-P25-Q25 -> 747.55193 | S25: =MAX(SUM(R14:R25),0)*Assumptions!$B$17 -> 0 | T25: =R25-S25 -> 747.55193 | U25: =U24+T25 -> 12897.177 | V25: =F25*Assumptions!$B$9*Assumptions!$B$21 -> 21775.407 | W25: =V25*12 -> 261304.88
A26: 25 | B26: =INT((A26-1)/12)+1 -> 3 | C26: =F25 -> 191.264 | D26: =C26*Assumptions!$B$20 -> 6.6942401 | E26: =Acquisition!B26*Assumptions!$B$19 -> 24 | F26: =C26-D26+E26 -> 208.56976 | G26: =C26-D26+E26/2 -> 196.56976 | H26: =G26*Assumptions!$B$9*Assumptions!$B$21 -> 22379.467 | I26: =H26*Assumptions!$B$11 -> 223.79467 | J26: =H26-I26 -> 22155.673 | K26: =H26*Assumptions!$B$12+G26*Assumptions!$B$13 -> 864.63175 | L26: =G26*(Assumptions!$B$14+Assumptions!$B$15) -> 2948.5464 | M26: =E26*Assumptions!$B$16 -> 1440 | N26: =SUM(K26:M26) -> 5253.1782 | O26: =J26-N26 -> 16902.495 | P26: =INDEX(Assumptions!$B$30:$D$30,1,B26) -> 22000 | Q26: =Acquisition!C26 -> 0 | R26: =O26-P26-Q26 -> -5097.5055 | S26: =0 -> 0 | T26: =R26-S26 -> -5097.5055 | U26: =U25+T26 -> 7799.6712 | V26: =F26*Assumptions!$B$9*Assumptions!$B$21 -> 23745.667 | W26: =V26*12 -> 284948.01
A27: 26 | B27: =INT((A27-1)/12)+1 -> 3 | C27: =F26 -> 208.56976 | D27: =C27*Assumptions!$B$20 -> 7.2999417 | E27: =Acquisition!B27*Assumptions!$B$19 -> 24 | F27: =C27-D27+E27 -> 225.26982 | G27: =C27-D27+E27/2 -> 213.26982 | H27: =G27*Assumptions!$B$9*Assumptions!$B$21 -> 24280.769 | I27: =H27*Assumptions!$B$11 -> 242.80769 | J27: =H27-I27 -> 24037.961 | K27: =H27*Assumptions!$B$12+G27*Assumptions!$B$13 -> 938.08863 | L27: =G27*(Assumptions!$B$14+Assumptions!$B$15) -> 3199.0473 | M27: =E27*Assumptions!$B$16 -> 1440 | N27: =SUM(K27:M27) -> 5577.1359 | O27: =J27-N27 -> 18460.825 | P27: =INDEX(Assumptions!$B$30:$D$30,1,B27) -> 22000 | Q27: =Acquisition!C27 -> 0 | R27: =O27-P27-Q27 -> -3539.1746 | S27: =0 -> 0 | T27: =R27-S27 -> -3539.1746 | U27: =U26+T27 -> 4260.4966 | V27: =F27*Assumptions!$B$9*Assumptions!$B$21 -> 25646.969 | W27: =V27*12 -> 307763.63
A28: 27 | B28: =INT((A28-1)/12)+1 -> 3 | C28: =F27 -> 225.26982 | D28: =C28*Assumptions!$B$20 -> 7.8844437 | E28: =Acquisition!B28*Assumptions!$B$19 -> 24 | F28: =C28-D28+E28 -> 241.38538 | G28: =C28-D28+E28/2 -> 229.38538 | H28: =G28*Assumptions!$B$9*Assumptions!$B$21 -> 26115.525 | I28: =H28*Assumptions!$B$11 -> 261.15525 | J28: =H28-I28 -> 25854.37 | K28: =H28*Assumptions!$B$12+G28*Assumptions!$B$13 -> 1008.9745 | L28: =G28*(Assumptions!$B$14+Assumptions!$B$15) -> 3440.7806 | M28: =E28*Assumptions!$B$16 -> 1440 | N28: =SUM(K28:M28) -> 5889.7552 | O28: =J28-N28 -> 19964.615 | P28: =INDEX(Assumptions!$B$30:$D$30,1,B28) -> 22000 | Q28: =Acquisition!C28 -> 0 | R28: =O28-P28-Q28 -> -2035.3853 | S28: =0 -> 0 | T28: =R28-S28 -> -2035.3853 | U28: =U27+T28 -> 2225.1113 | V28: =F28*Assumptions!$B$9*Assumptions!$B$21 -> 27481.725 | W28: =V28*12 -> 329780.7
A29: 28 | B29: =INT((A29-1)/12)+1 -> 3 | C29: =F28 -> 241.38538 | D29: =C29*Assumptions!$B$20 -> 8.4484882 | E29: =Acquisition!B29*Assumptions!$B$19 -> 24 | F29: =C29-D29+E29 -> 256.93689 | G29: =C29-D29+E29/2 -> 244.93689 | H29: =G29*Assumptions!$B$9*Assumptions!$B$21 -> 27886.065 | I29: =H29*Assumptions!$B$11 -> 278.86065 | J29: =H29-I29 -> 27607.204 | K29: =H29*Assumptions!$B$12+G29*Assumptions!$B$13 -> 1077.3794 | L29: =G29*(Assumptions!$B$14+Assumptions!$B$15) -> 3674.0533 | M29: =E29*Assumptions!$B$16 -> 1440 | N29: =SUM(K29:M29) -> 6191.4327 | O29: =J29-N29 -> 21415.771 | P29: =INDEX(Assumptions!$B$30:$D$30,1,B29) -> 22000 | Q29: =Acquisition!C29 -> 0 | R29: =O29-P29-Q29 -> -584.22864 | S29: =0 -> 0 | T29: =R29-S29 -> -584.22864 | U29: =U28+T29 -> 1640.8827 | V29: =F29*Assumptions!$B$9*Assumptions!$B$21 -> 29252.265 | W29: =V29*12 -> 351027.18
A30: 29 | B30: =INT((A30-1)/12)+1 -> 3 | C30: =F29 -> 256.93689 | D30: =C30*Assumptions!$B$20 -> 8.9927911 | E30: =Acquisition!B30*Assumptions!$B$19 -> 24 | F30: =C30-D30+E30 -> 271.9441 | G30: =C30-D30+E30/2 -> 259.9441 | H30: =G30*Assumptions!$B$9*Assumptions!$B$21 -> 29594.635 | I30: =H30*Assumptions!$B$11 -> 295.94635 | J30: =H30-I30 -> 29298.689 | K30: =H30*Assumptions!$B$12+G30*Assumptions!$B$13 -> 1143.3901 | L30: =G30*(Assumptions!$B$14+Assumptions!$B$15) -> 3899.1615 | M30: =E30*Assumptions!$B$16 -> 1440 | N30: =SUM(K30:M30) -> 6482.5516 | O30: =J30-N30 -> 22816.138 | P30: =INDEX(Assumptions!$B$30:$D$30,1,B30) -> 22000 | Q30: =Acquisition!C30 -> 0 | R30: =O30-P30-Q30 -> 816.13755 | S30: =0 -> 0 | T30: =R30-S30 -> 816.13755 | U30: =U29+T30 -> 2457.0202 | V30: =F30*Assumptions!$B$9*Assumptions!$B$21 -> 30960.835 | W30: =V30*12 -> 371530.03
A31: 30 | B31: =INT((A31-1)/12)+1 -> 3 | C31: =F30 -> 271.9441 | D31: =C31*Assumptions!$B$20 -> 9.5180434 | E31: =Acquisition!B31*Assumptions!$B$19 -> 24 | F31: =C31-D31+E31 -> 286.42605 | G31: =C31-D31+E31/2 -> 274.42605 | H31: =G31*Assumptions!$B$9*Assumptions!$B$21 -> 31243.406 | I31: =H31*Assumptions!$B$11 -> 312.43406 | J31: =H31-I31 -> 30930.972 | K31: =H31*Assumptions!$B$12+G31*Assumptions!$B$13 -> 1207.0904 | L31: =G31*(Assumptions!$B$14+Assumptions!$B$15) -> 4116.3908 | M31: =E31*Assumptions!$B$16 -> 1440 | N31: =SUM(K31:M31) -> 6763.4812 | O31: =J31-N31 -> 24167.491 | P31: =INDEX(Assumptions!$B$30:$D$30,1,B31) -> 22000 | Q31: =Acquisition!C31 -> 0 | R31: =O31-P31-Q31 -> 2167.4909 | S31: =0 -> 0 | T31: =R31-S31 -> 2167.4909 | U31: =U30+T31 -> 4624.5111 | V31: =F31*Assumptions!$B$9*Assumptions!$B$21 -> 32609.606 | W31: =V31*12 -> 391315.27
A32: 31 | B32: =INT((A32-1)/12)+1 -> 3 | C32: =F31 -> 286.42605 | D32: =C32*Assumptions!$B$20 -> 10.024912 | E32: =Acquisition!B32*Assumptions!$B$19 -> 24 | F32: =C32-D32+E32 -> 300.40114 | G32: =C32-D32+E32/2 -> 288.40114 | H32: =G32*Assumptions!$B$9*Assumptions!$B$21 -> 32834.47 | I32: =H32*Assumptions!$B$11 -> 328.3447 | J32: =H32-I32 -> 32506.125 | K32: =H32*Assumptions!$B$12+G32*Assumptions!$B$13 -> 1268.5613 | L32: =G32*(Assumptions!$B$14+Assumptions!$B$15) -> 4326.0171 | M32: =E32*Assumptions!$B$16 -> 1440 | N32: =SUM(K32:M32) -> 7034.5784 | O32: =J32-N32 -> 25471.547 | P32: =INDEX(Assumptions!$B$30:$D$30,1,B32) -> 22000 | Q32: =Acquisition!C32 -> 0 | R32: =O32-P32-Q32 -> 3471.5469 | S32: =0 -> 0 | T32: =R32-S32 -> 3471.5469 | U32: =U31+T32 -> 8096.058 | V32: =F32*Assumptions!$B$9*Assumptions!$B$21 -> 34200.67 | W32: =V32*12 -> 410408.04
A33: 32 | B33: =INT((A33-1)/12)+1 -> 3 | C33: =F32 -> 300.40114 | D33: =C33*Assumptions!$B$20 -> 10.51404 | E33: =Acquisition!B33*Assumptions!$B$19 -> 24 | F33: =C33-D33+E33 -> 313.8871 | G33: =C33-D33+E33/2 -> 301.8871 | H33: =G33*Assumptions!$B$9*Assumptions!$B$21 -> 34369.847 | I33: =H33*Assumptions!$B$11 -> 343.69847 | J33: =H33-I33 -> 34026.148 | K33: =H33*Assumptions!$B$12+G33*Assumptions!$B$13 -> 1327.8806 | L33: =G33*(Assumptions!$B$14+Assumptions!$B$15) -> 4528.3065 | M33: =E33*Assumptions!$B$16 -> 1440 | N33: =SUM(K33:M33) -> 7296.1871 | O33: =J33-N33 -> 26729.961 | P33: =INDEX(Assumptions!$B$30:$D$30,1,B33) -> 22000 | Q33: =Acquisition!C33 -> 0 | R33: =O33-P33-Q33 -> 4729.961 | S33: =0 -> 0 | T33: =R33-S33 -> 4729.961 | U33: =U32+T33 -> 12826.019 | V33: =F33*Assumptions!$B$9*Assumptions!$B$21 -> 35736.047 | W33: =V33*12 -> 428832.56
